<?xml version="1.0" ?>
<!-- =================================================================================== -->
<!-- |    This document was autogenerated by xacro from model.urdf.xacro               | -->
<!-- |    EDITING THIS FILE BY HAND IS NOT RECOMMENDED                                 | -->
<!-- =================================================================================== -->
<sdf version="1.5">
  <model name="mrsim-omnimorph">
    <link name="base">
      <inertial>
        <pose>0 0.250 0 0 0 0</pose>
        <mass>1.625</mass>
        <inertia>
          <ixx>0.0332</ixx>
          <ixy>0</ixy>
          <ixz>0</ixz>
          <iyy>0.01138</iyy>
          <iyz>0</iyz>
          <izz>0.0332</izz>
        </inertia>
      </inertial>
      <collision name="base">
        <geometry>
          <box>
            <size>0.05 0.05 0.05</size>
          </box>
        </geometry>
      </collision>
      <collision name="effector_collision">
        <pose>0 0.238 0 0 1.57079 1.57079</pose>
        <!--<pose>0.26642 0.26642 0 0 1.57079 0.78539</pose>-->
        <geometry>
          <cylinder>
            <radius>0.004</radius>
            <length>0.476</length>
          </cylinder>
        </geometry>
      </collision>
      <collision name="effector_tip_collision">
        <pose>0 0.476 0 0 0 0</pose>
        <geometry>
          <sphere>
            <radius>0.004</radius>
          </sphere>
        </geometry>
      </collision>
      <visual name="main_frame">
        <pose>0 0 0 0 0 0</pose>
        <geometry>
          <mesh>
            <uri>model://mrsim-omnimorph/omnicopter_frame.stl</uri>
            <scale>0.001 0.001 0.001 </scale>
          </mesh>
        </geometry>
        <material>
          <ambient>0 0 0 0.8</ambient>
          <diffuse>1.0 1.0 1.0 1</diffuse>
        </material>
      </visual>
      <visual name="effector_tip_visual">
        <pose>0 0.476 0 0 0 0</pose>
        <geometry>
            <sphere>
             <radius>0.004</radius>
             </sphere>
        </geometry>
      </visual>
      <visual name="effector_visual">
        <pose>0 0.238 0 0 1.57079 1.57079</pose>
        <geometry>
          <cylinder>
            <radius>0.004</radius>
            <length>0.476</length>
          </cylinder>
        </geometry>
      </visual>
      <!--<visual name="effector_visual">
        <pose>-0.02 0 0 0 0 0</pose>
        <geometry>
          <mesh>
            <uri>model://mrsim-omnimorph/visualization_stick50cm_xaxis.stl</uri>
            <scale>0.001 0.001 0.001 </scale>
          </mesh>
        </geometry>
      </visual> -->      
      <!--<visual name="sphere_visual">
        <pose>0 0 0 0 0 0</pose>
        <geometry>
            <sphere>
             <radius>0.31</radius>
             </sphere>
        </geometry>
      </visual>-->
    </link>
    <link name="m1">
      <pose>0.125 0.125 0.125 0 0 0 </pose>
      <inertial>
        <mass>0.0001</mass>
        <inertia>
          <ixx>0.0001</ixx>
          <ixy>0</ixy>
          <ixz>0</ixz>
          <iyy>0.0001</iyy>
          <iyz>0</iyz>
          <izz>0.0001</izz>
        </inertia>
      </inertial>
      <visual name="motor">
        <pose>0 0 0 0 0 0</pose>
        <geometry>
          <mesh>
            <uri>model://mrsim-omnimorph/brushless_motor_f40.stl</uri>
            <scale>0.001 0.001 0.001 </scale>
          </mesh>
        </geometry>
        <material>
          <ambient>76 6 6 0.65</ambient>
          <diffuse>1.0 1.0 1.0 1</diffuse>
        </material>
      </visual>
      <visual name="rot_axis">
        <pose>0 0 0 0 0 1.5708</pose>
        <geometry>
          <mesh>
            <uri>model://mrsim-omnimorph/rotationaxis.stl</uri>
            <scale>0.001 0.001 0.001 </scale>
          </mesh>
        </geometry>
        <material>
          <ambient>76 6 6 0.65</ambient>
          <diffuse>1.0 1.0 1.0 1</diffuse>
        </material>
      </visual>
    </link>
    <link name="m1a">
      <pose>0.125 0.125 0.125 0 0 0</pose>
      <inertial>
        <mass>0.0001</mass>
        <inertia>
          <ixx>0.0001</ixx>
          <ixy>0</ixy>
          <ixz>0</ixz>
          <iyy>0.0001</iyy>
          <iyz>0</iyz>
          <izz>0.0001</izz>
        </inertia>
      </inertial>
    </link>
    <link name="m2">
      <pose>-0.125 0.125 0.125 0 0 0 </pose>
      <inertial>
        <mass>0.0001</mass>
        <inertia>
          <ixx>0.0001</ixx>
          <ixy>0</ixy>
          <ixz>0</ixz>
          <iyy>0.0001</iyy>
          <iyz>0</iyz>
          <izz>0.0001</izz>
        </inertia>
      </inertial>
      <visual name="motor">
        <pose>0 0 0 0 0 0</pose>
        <geometry>
          <mesh>
            <uri>model://mrsim-omnimorph/brushless_motor_f40.stl</uri>
            <scale>0.001 0.001 0.001 </scale>
          </mesh>
        </geometry>
        <material>
          <ambient>76 6 6 0.65</ambient>
          <diffuse>1.0 1.0 1.0 1</diffuse>
        </material>
      </visual>
      <visual name="rot_axis">
        <pose>0 0 0 0 0 0</pose>
        <geometry>
          <mesh>
            <uri>model://mrsim-omnimorph/rotationaxis.stl</uri>
            <scale>0.001 0.001 0.001 </scale>
          </mesh>
        </geometry>
      </visual>
    </link>
        <link name="m2a">
      <pose>-0.125 0.125 0.125 0 0 0</pose>
      <inertial>
        <mass>0.0001</mass>
        <inertia>
          <ixx>0.0001</ixx>
          <ixy>0</ixy>
          <ixz>0</ixz>
          <iyy>0.0001</iyy>
          <iyz>0</iyz>
          <izz>0.0001</izz>
        </inertia>
      </inertial>
    </link>
    <link name="m3">
      <pose>-0.125 -0.125 0.125 0 0 0 </pose>
      <inertial>
        <mass>0.0001</mass>
        <inertia>
          <ixx>0.0001</ixx>
          <ixy>0</ixy>
          <ixz>0</ixz>
          <iyy>0.0001</iyy>
          <iyz>0</iyz>
          <izz>0.0001</izz>
        </inertia>
      </inertial>
      <visual name="motor">
        <pose>0 0 0 0 0 0</pose>
        <geometry>
          <mesh>
            <uri>model://mrsim-omnimorph/brushless_motor_f40.stl</uri>
            <scale>0.001 0.001 0.001 </scale>
          </mesh>
        </geometry>
        <material>
          <ambient>76 6 6 0.65</ambient>
          <diffuse>1.0 1.0 1.0 1</diffuse>
        </material>
      </visual>
      <visual name="rot_axis">
        <pose>0 0 0 0 0 -1.5708</pose>
        <geometry>
          <mesh>
            <uri>model://mrsim-omnimorph/rotationaxis.stl</uri>
            <scale>0.001 0.001 0.001 </scale>
          </mesh>
        </geometry>
      </visual>
    </link>
     <link name="m3a">
      <pose>-0.125 -0.125 0.125 0 0 0</pose>
      <inertial>
        <mass>0.0001</mass>
        <inertia>
          <ixx>0.0001</ixx>
          <ixy>0</ixy>
          <ixz>0</ixz>
          <iyy>0.0001</iyy>
          <iyz>0</iyz>
          <izz>0.0001</izz>
        </inertia>
      </inertial>
    </link>   
    <link name="m4">
      <pose>0.125 -0.125 0.125 0 0 0 </pose>
      <inertial>
        <mass>0.0001</mass>
        <inertia>
          <ixx>0.0001</ixx>
          <ixy>0</ixy>
          <ixz>0</ixz>
          <iyy>0.0001</iyy>
          <iyz>0</iyz>
          <izz>0.0001</izz>
        </inertia>
      </inertial>
      <visual name="motor">
        <pose>0 0 0 0 0 0</pose>
        <geometry>
          <mesh>
            <uri>model://mrsim-omnimorph/brushless_motor_f40.stl</uri>
            <scale>0.001 0.001 0.001 </scale>
          </mesh>
        </geometry>
        <material>
          <ambient>76 6 6 0.65</ambient>
          <diffuse>1.0 1.0 1.0 1</diffuse>
        </material>
      </visual>
      <visual name="rot_axis">
        <pose>0 0 0 0 0 0</pose>
        <geometry>
          <mesh>
            <uri>model://mrsim-omnimorph/rotationaxis.stl</uri>
            <scale>0.001 0.001 0.001 </scale>
          </mesh>
        </geometry>
      </visual>
    </link>
    <link name="m4a">
      <pose>0.125 -0.125 0.125 0 0 0</pose>
      <inertial>
        <mass>0.0001</mass>
        <inertia>
          <ixx>0.0001</ixx>
          <ixy>0</ixy>
          <ixz>0</ixz>
          <iyy>0.0001</iyy>
          <iyz>0</iyz>
          <izz>0.0001</izz>
        </inertia>
      </inertial>
    </link>    
    <link name="m5">
      <pose>0.125 0.125 -0.125 0 0 0 </pose>
      <inertial>
        <mass>0.0001</mass>
        <inertia>
          <ixx>0.0001</ixx>
          <ixy>0</ixy>
          <ixz>0</ixz>
          <iyy>0.0001</iyy>
          <iyz>0</iyz>
          <izz>0.0001</izz>
        </inertia>
      </inertial>
      <visual name="motor">
        <pose>0 0 0 0 3.14159 0</pose>
        <geometry>
          <mesh>
            <uri>model://mrsim-omnimorph/brushless_motor_f40.stl</uri>
            <scale>0.001 0.001 0.001 </scale>
          </mesh>
        </geometry>
        <material>
          <ambient>76 6 6 0.65</ambient>
          <diffuse>1.0 1.0 1.0 1</diffuse>
        </material>
      </visual>
      <visual name="rot_axis">
        <pose>0 0 0 0 0 1.5708</pose>
        <geometry>
          <mesh>
            <uri>model://mrsim-omnimorph/rotationaxis.stl</uri>
            <scale>0.001 0.001 0.001 </scale>
          </mesh>
        </geometry>
      </visual>
    </link>
    <link name="m5a">
      <pose>0.125 0.125 -0.125 0 0 0</pose>
      <inertial>
        <mass>0.0001</mass>
        <inertia>
          <ixx>0.0001</ixx>
          <ixy>0</ixy>
          <ixz>0</ixz>
          <iyy>0.0001</iyy>
          <iyz>0</iyz>
          <izz>0.0001</izz>
        </inertia>
      </inertial>
    </link>
    <link name="m6">
      <pose>-0.125 0.125 -0.125 0 0 0 </pose>
      <inertial>
        <mass>0.0001</mass>
        <inertia>
          <ixx>0.0001</ixx>
          <ixy>0</ixy>
          <ixz>0</ixz>
          <iyy>0.0001</iyy>
          <iyz>0</iyz>
          <izz>0.0001</izz>
        </inertia>
      </inertial>
      <visual name="motor">
        <pose>0 0 0 0 3.14159 0</pose>
        <geometry>
          <mesh>
            <uri>model://mrsim-omnimorph/brushless_motor_f40.stl</uri>
            <scale>0.001 0.001 0.001 </scale>
          </mesh>
        </geometry>
        <material>
          <ambient>76 6 6 0.65</ambient>
          <diffuse>1.0 1.0 1.0 1</diffuse>
        </material>
      </visual>
      <visual name="rot_axis">
        <pose>0 0 0 0 0 0</pose>
        <geometry>
          <mesh>
            <uri>model://mrsim-omnimorph/rotationaxis.stl</uri>
            <scale>0.001 0.001 0.001 </scale>
          </mesh>
        </geometry>
      </visual>
    </link>
    <link name="m6a">
      <pose>-0.125 0.125 -0.125 0 0 0</pose>
      <inertial>
        <mass>0.0001</mass>
        <inertia>
          <ixx>0.0001</ixx>
          <ixy>0</ixy>
          <ixz>0</ixz>
          <iyy>0.0001</iyy>
          <iyz>0</iyz>
          <izz>0.0001</izz>
        </inertia>
      </inertial>
    </link>
    <link name="m7">
      <pose>-0.125 -0.125 -0.125 0 0 0 </pose>
      <inertial>
        <mass>0.0001</mass>
        <inertia>
          <ixx>0.0001</ixx>
          <ixy>0</ixy>
          <ixz>0</ixz>
          <iyy>0.0001</iyy>
          <iyz>0</iyz>
          <izz>0.0001</izz>
        </inertia>
      </inertial>
      <visual name="motor">
        <pose>0 0 0 0 3.14159 0</pose>
        <geometry>
          <mesh>
            <uri>model://mrsim-omnimorph/brushless_motor_f40.stl</uri>
            <scale>0.001 0.001 0.001 </scale>
          </mesh>
        </geometry>
        <material>
          <ambient>76 6 6 0.65</ambient>
          <diffuse>1.0 1.0 1.0 1</diffuse>
        </material>
      </visual>
      <visual name="rot_axis">
        <pose>0 0 0 0 0 1.5708</pose>
        <geometry>
          <mesh>
            <uri>model://mrsim-omnimorph/rotationaxis.stl</uri>
            <scale>0.001 0.001 0.001 </scale>
          </mesh>
        </geometry>
      </visual>
    </link>
    <link name="m7a">
      <pose>-0.125 -0.125 -0.125 0 0 0</pose>
      <inertial>
        <mass>0.0001</mass>
        <inertia>
          <ixx>0.0001</ixx>
          <ixy>0</ixy>
          <ixz>0</ixz>
          <iyy>0.0001</iyy>
          <iyz>0</iyz>
          <izz>0.0001</izz>
        </inertia>
      </inertial>
    </link>
    <link name="m8">
      <pose>0.125 -0.125 -0.125 0 0 0 </pose>
      <inertial>
        <mass>0.0001</mass>
        <inertia>
          <ixx>0.0001</ixx>
          <ixy>0</ixy>
          <ixz>0</ixz>
          <iyy>0.0001</iyy>
          <iyz>0</iyz>
          <izz>0.0001</izz>
        </inertia>
      </inertial>
      <visual name="motor">
        <pose>0 0 0 0 3.14159 0</pose>
        <geometry>
          <mesh>
            <uri>model://mrsim-omnimorph/brushless_motor_f40.stl</uri>
            <scale>0.001 0.001 0.001 </scale>
          </mesh>
        </geometry>
        <material>
          <ambient>76 6 6 0.65</ambient>
          <diffuse>1.0 1.0 1.0 1</diffuse>
        </material>
      </visual>
      <visual name="rot_axis">
        <pose>0 0 0 0 0 0</pose>
        <geometry>
          <mesh>
            <uri>model://mrsim-omnimorph/rotationaxis.stl</uri>
            <scale>0.001 0.001 0.001 </scale>
          </mesh>
        </geometry>
      </visual>
    </link>
    <link name="m8a">
      <pose>0.125 -0.125 -0.125 0 0 0</pose>
      <inertial>
        <mass>0.0001</mass>
        <inertia>
          <ixx>0.0001</ixx>
          <ixy>0</ixy>
          <ixz>0</ixz>
          <iyy>0.0001</iyy>
          <iyz>0</iyz>
          <izz>0.0001</izz>
        </inertia>
      </inertial>
    </link>
    <joint name="jm_pitch-1" type="revolute">
      <parent>base</parent>
      <child>m1a</child>
      <axis>
     <xyz>0 1 0</xyz>
      </axis>
    </joint>
    <joint name="jm_roll-1" type="revolute">
      <parent>m1a</parent>
      <child>m1</child>
      <axis>
     <xyz>1 0 0</xyz>
      </axis>
    </joint>
    <joint name="jm_pitch-2" type="revolute">
      <parent>base</parent>
      <child>m2a</child>
      <axis>
     <xyz>0 1 0</xyz>
      </axis>
    </joint>
    <joint name="jm_roll-2" type="revolute">
      <parent>m2a</parent>
      <child>m2</child>
      <axis>
     <xyz>1 0 0</xyz>
      </axis>
    </joint>
    <joint name="jm_pitch-3" type="revolute">
      <parent>base</parent>
      <child>m3a</child>
      <axis>
     <xyz>0 1 0</xyz>
      </axis>
    </joint>
    <joint name="jm_roll-3" type="revolute">
      <parent>m3a</parent>
      <child>m3</child>
      <axis>
     <xyz>1 0 0</xyz>
      </axis>
    </joint>
    <joint name="jm_pitch-4" type="revolute">
      <parent>base</parent>
      <child>m4a</child>
      <axis>
     <xyz>0 1 0</xyz>
      </axis>
    </joint>
    <joint name="jm_roll-4" type="revolute">
      <parent>m4a</parent>
      <child>m4</child>
      <axis>
     <xyz>1 0 0</xyz>
      </axis>
    </joint>
    <joint name="jm_pitch-5" type="revolute">
      <parent>base</parent>
      <child>m5a</child>
      <axis>
     <xyz>0 1 0</xyz>
      </axis>
    </joint>
    <joint name="jm_roll-5" type="revolute">
      <parent>m5a</parent>
      <child>m5</child>
      <axis>
     <xyz>1 0 0</xyz>
      </axis>
    </joint>
    <joint name="jm_pitch-6" type="revolute">
      <parent>base</parent>
      <child>m6a</child>
      <axis>
     <xyz>0 1 0</xyz>
      </axis>
    </joint>
    <joint name="jm_roll-6" type="revolute">
      <parent>m6a</parent>
      <child>m6</child>
      <axis>
     <xyz>1 0 0</xyz>
      </axis>
    </joint>
    <joint name="jm_pitch-7" type="revolute">
      <parent>base</parent>
      <child>m7a</child>
      <axis>
     <xyz>0 1 0</xyz>
      </axis>
    </joint>
    <joint name="jm_roll-7" type="revolute">
      <parent>m7a</parent>
      <child>m7</child>
      <axis>
     <xyz>1 0 0</xyz>
      </axis>
    </joint>
    <joint name="jm_pitch-8" type="revolute">
      <parent>base</parent>
      <child>m8a</child>
      <axis>
     <xyz>0 1 0</xyz>
      </axis>
    </joint>
    <joint name="jm_roll-8" type="revolute">
      <parent>m8a</parent>
      <child>m8</child>
      <axis>
     <xyz>1 0 0</xyz>
      </axis>
    </joint>
    <include>
      <uri>model://mrsim-tiltrotor</uri>
      <name>rotor-1</name>
      <pose>0.125 0.125 0.125 0 0 0 </pose>
    </include>
    <joint name="jrotor-1" type="revolute">
      <parent>m1</parent>
      <child>rotor-1::propeller</child>
      <axis>
        <xyz>0 0 1</xyz>
      </axis>
    </joint>
    <include>
      <uri>model://mrsim-tiltrotor</uri>
      <name>rotor-2</name>
      <pose>-0.125 0.125 0.125 0 0 0</pose>
    </include>
    <joint name="jrotor-2" type="revolute">
      <parent>m2</parent>
      <child>rotor-2::propeller</child>
      <axis>
        <xyz>0 0 1</xyz>
      </axis>
    </joint>
    <include>
      <uri>model://mrsim-tiltrotor</uri>
      <name>rotor-3</name>
      <pose>-0.125 -0.125 0.125 0 0 0</pose>
    </include>
    <joint name="jrotor-3" type="revolute">
      <parent>m3</parent>
      <child>rotor-3::propeller</child>
      <axis>
        <xyz>0 0 1</xyz>
      </axis>
    </joint>
    <include>
      <uri>model://mrsim-tiltrotor</uri>
      <name>rotor-4</name>
      <pose>0.125 -0.125 0.125 0 0 0</pose>
    </include>
    <joint name="jrotor-4" type="revolute">
      <parent>m4</parent>
      <child>rotor-4::propeller</child>
      <axis>
        <xyz>0 0 1</xyz>
      </axis>
    </joint>
    <include>
      <uri>model://mrsim-tiltrotor_l</uri>
      <name>rotor-5</name>
      <pose>0.125 0.125 -0.125 0 0 0</pose>
    </include>
    <joint name="jrotor-5" type="revolute">
      <parent>m5</parent>
      <child>rotor-5::propeller</child>
      <axis>
        <xyz>0 0 1</xyz>
      </axis>
    </joint>
    <include>
      <uri>model://mrsim-tiltrotor_l</uri>
      <name>rotor-6</name>
      <pose>-0.125 0.125 -0.125 0 0 0</pose>
    </include>
    <joint name="jrotor-6" type="revolute">
      <parent>m6</parent>
      <child>rotor-6::propeller</child>
      <axis>
        <xyz>0 0 1</xyz>
      </axis>
    </joint>
    <include>
      <uri>model://mrsim-tiltrotor_l</uri>
      <name>rotor-7</name>
      <pose>-0.125 -0.125 -0.125 0 0 0</pose>
    </include>
    <joint name="jrotor-7" type="revolute">
      <parent>m7</parent>
      <child>rotor-7::propeller</child>
      <axis>
        <xyz>0 0 1</xyz>
      </axis>
    </joint>
    <include>
      <uri>model://mrsim-tiltrotor_l</uri>
      <name>rotor-8</name>
      <pose>0.125 -0.125 -0.125 0 0 0</pose>
    </include>
    <joint name="jrotor-8" type="revolute">
      <parent>m8</parent>
      <child>rotor-8::propeller</child>
      <axis>
        <xyz>0 0 1</xyz>
      </axis>
    </joint>
    <plugin filename="mrsim-gazebo.so" name="mrsim">
      <link>base</link>
      <rotors>
        <cf>1.5e-4</cf>
        <ct>2.2e-6</ct>
        <I>70</I>
        <V>25</V>
        <rotor>
          <joint spin="cw">jrotor-1</joint>
        </rotor>
        <rotor>
          <joint spin="ccw">jrotor-2</joint>
        </rotor>
        <rotor>
          <joint spin="cw">jrotor-3</joint>
        </rotor>
        <rotor>
          <joint spin="ccw">jrotor-4</joint>
        </rotor>
        <rotor>
          <joint spin="cw">jrotor-5</joint>
        </rotor>
        <rotor>
          <joint spin="ccw">jrotor-6</joint>
        </rotor>
        <rotor>
          <joint spin="cw">jrotor-7</joint>
        </rotor>
        <rotor>
          <joint spin="ccw">jrotor-8</joint>
        </rotor>
      </rotors>
    </plugin>
    <plugin name="dxsim_pitch" filename="dxsim-gazebo.so">
    <pty>/tmp/pty-dynamixel-pitch</pty>
    <period>1e-3</period>
    <motors>
      <motor>
        <joint spin="ccw">jm_pitch-1</joint>
        <eeprom>$HOME/openrobots/share/gazebo/eeprom/dx_eeprom_id1</eeprom>
        <model>MX64T</model>
        <p0>0.0</p0>
        <v0>0.0</v0>
        <id>1</id>
        <noise>0</noise>
        <debug>0</debug>
      </motor>
      <motor>
        <joint spin="ccw">jm_pitch-2</joint>
        <eeprom>$HOME/openrobots/share/gazebo/eeprom/dx_eeprom_id2</eeprom>
        <model>MX64T</model>
        <p0>0.0</p0>
        <v0>0.0</v0>
        <id>2</id>
        <noise>0</noise>
        <debug>0</debug>
      </motor>
            <motor>
        <joint spin="ccw">jm_pitch-3</joint>
        <eeprom>$HOME/openrobots/share/gazebo/eeprom/dx_eeprom_id3</eeprom>
        <model>MX64T</model>
        <p0>0.0</p0>
        <v0>0.0</v0>
        <id>3</id>
        <noise>0</noise>
        <debug>0</debug>
      </motor>
            <motor>
        <joint spin="ccw">jm_pitch-4</joint>
        <eeprom>$HOME/openrobots/share/gazebo/eeprom/dx_eeprom_id4</eeprom>
        <model>MX64T</model>
        <p0>0.0</p0>
        <v0>0.0</v0>
        <id>4</id>
        <noise>0</noise>
        <debug>0</debug>
      </motor>
            <motor>
        <joint spin="ccw">jm_pitch-5</joint>
        <eeprom>$HOME/openrobots/share/gazebo/eeprom/dx_eeprom_id5</eeprom>
        <model>MX64T</model>
        <p0>0.0</p0>
        <v0>0.0</v0>
        <id>5</id>
        <noise>0</noise>
        <debug>0</debug>
      </motor>
            <motor>
        <joint spin="ccw">jm_pitch-6</joint>
        <eeprom>$HOME/openrobots/share/gazebo/eeprom/dx_eeprom_id6</eeprom>
        <model>MX64T</model>
        <p0>0.0</p0>
        <v0>0.0</v0>
        <id>6</id>
        <noise>0</noise>
        <debug>0</debug>
      </motor>
            <motor>
        <joint spin="ccw">jm_pitch-7</joint>
        <eeprom>$HOME/openrobots/share/gazebo/eeprom/dx_eeprom_id7</eeprom>
        <model>MX64T</model>
        <p0>0.0</p0>
        <v0>0.0</v0>
        <id>7</id>
        <noise>0</noise>
        <debug>0</debug>
      </motor>
            <motor>
        <joint spin="ccw">jm_pitch-8</joint>
        <eeprom>$HOME/openrobots/share/gazebo/eeprom/dx_eeprom_id8</eeprom>
        <model>MX64T</model>
        <p0>0.0</p0>
        <v0>0.0</v0>
        <id>8</id>
        <noise>0</noise>
        <debug>0</debug>
      </motor>
     </motors>
  </plugin>
  <plugin name="dxsim_roll" filename="dxsim-gazebo.so">
  <pty>/tmp/pty-dynamixel-roll</pty>
  <period>1e-3</period>
    <motors>
      <motor>
        <joint spin="ccw">jm_roll-1</joint>
        <eeprom>$HOME/openrobots/share/gazebo/eeprom/dx_eeprom_id9</eeprom>
        <model>MX64T</model>
        <p0>0.0</p0>
        <v0>0.0</v0>
        <id>1</id>
        <noise>0</noise>
        <debug>0</debug>
      </motor>
      <motor>
        <joint spin="ccw">jm_roll-2</joint>
        <eeprom>$HOME/openrobots/share/gazebo/eeprom/dx_eeprom_id10</eeprom>
        <model>MX64T</model>
        <p0>0.0</p0>
        <v0>0.0</v0>
        <id>2</id>
        <noise>0</noise>
        <debug>0</debug>
      </motor>
            <motor>
        <joint spin="ccw">jm_roll-3</joint>
        <eeprom>$HOME/openrobots/share/gazebo/eeprom/dx_eeprom_id11</eeprom>
        <model>MX64T</model>
        <p0>0.0</p0>
        <v0>0.0</v0>
        <id>3</id>
        <noise>0</noise>
        <debug>0</debug>
      </motor>
            <motor>
        <joint spin="ccw">jm_roll-4</joint>
        <eeprom>$HOME/openrobots/share/gazebo/eeprom/dx_eeprom_id12</eeprom>
        <model>MX64T</model>
        <p0>0.0</p0>
        <v0>0.0</v0>
        <id>4</id>
        <noise>0</noise>
        <debug>0</debug>
      </motor>
            <motor>
        <joint spin="ccw">jm_roll-5</joint>
        <eeprom>$HOME/openrobots/share/gazebo/eeprom/dx_eeprom_id13</eeprom>
        <model>MX64T</model>
        <p0>0.0</p0>
        <v0>0.0</v0>
        <id>5</id>
        <noise>0</noise>
        <debug>0</debug>
      </motor>
            <motor>
        <joint spin="ccw">jm_roll-6</joint>
        <eeprom>$HOME/openrobots/share/gazebo/eeprom/dx_eeprom_id14</eeprom>
        <model>MX64T</model>
        <p0>0.0</p0>
        <v0>0.0</v0>
        <id>6</id>
        <noise>0</noise>
        <debug>0</debug>
      </motor>
            <motor>
        <joint spin="ccw">jm_roll-7</joint>
        <eeprom>$HOME/openrobots/share/gazebo/eeprom/dx_eeprom_id15</eeprom>
        <model>MX64T</model>
        <p0>0.0</p0>
        <v0>0.0</v0>
        <id>7</id>
        <noise>0</noise>
        <debug>0</debug>
      </motor>
            <motor>
        <joint spin="ccw">jm_roll-8</joint>
        <eeprom>$HOME/openrobots/share/gazebo/eeprom/dx_eeprom_id16</eeprom>
        <model>MX64T</model>
        <p0>0.0</p0>
        <v0>0.0</v0>
        <id>8</id>
        <noise>0</noise>
        <debug>0</debug>
      </motor>
    </motors>
  </plugin>
  </model>
</sdf>

